package pointers_errors

import (
	"testing"
)

func TestWallet(t *testing.T) {

	t.Run("Deposit", func(t *testing.T) {
		wallet := Wallet{}
		wallet.Deposit(Bitcoin(10))
		assertBalance(t, wallet, Bitcoin(10))
	})

	t.Run("Withdraw with funds", func(t *testing.T) {
		wallet := Wallet{balance: Bitcoin(20)}
		err := wallet.Withdraw(Bitcoin(10))
		assertBalance(t, wallet, Bitcoin(10))
		assertNoError(t, err)
	})

	t.Run("Withdraw insufficient funds", func(t *testing.T) {

		wallet := Wallet{Bitcoin(20)}
		err := wallet.Withdraw(Bitcoin(100))
		assertError(t, err, "cannot withdraw, insufficient funds")
		assertBalance(t, wallet, Bitcoin(20))
	})
}

func assertBalance(t *testing.T, wallet Wallet, want Bitcoin) {
	t.Helper()
	got := wallet.Balance()

	if got != want {
		t.Errorf("got %s want %s", got, want)
	}
}

func assertError(t *testing.T, got error, want string) {
	t.Helper()
	if got == nil {
		t.Fatal("wanted an error but didn't get one")
	} else if got.Error() != want {
		t.Errorf("got %q, want %q", got, want)
	}
}

func assertNoError(t *testing.T, got error) {
	if got != nil {
		t.Fatal("got an error but didnt want one")
	}
}
